Workbook

Sheet Fees Master
B1: S.No | C1: Class | D1: School Fees | F1: S.No | G1: Class | H1: Total Fees | I1: Hostel Fees | K1: S.No | L1: Village | M1: Bus Fees
B2: 1 | C2: N - AM | D2: 7500 | F2: 1 | G2: N - AM | H2: 22000 | I2: =H2-D2 -> 14500 | K2: 1 | L2: ACHANPALLY | M2: 5000
B3: 2 | C3: N - AS | D3: 7500 | F3: 2 | G3: N - AS | H3: 22000 | I3: =H3-D3 -> 14500 | K3: 2 | L3: AMBEDKAR COLONY | M3: 5000
B4: 3 | C4: L - AM | D4: 8500 | F4: 3 | G4: L - AM | H4: 23000 | I4: =H4-D4 -> 14500 | K4: 3 | L4: AMBEDKAR NAGAR, RENJAL | M4: 8000
B5: 4 | C5: L - AS | D5: 8500 | F5: 4 | G5: L - AS | H5: 23000 | I5: =H5-D5 -> 14500 | K5: 4 | L5: AMDAPUR | M5: 9999
B6: 5 | C6: L - BM | D6: 8500 | F6: 5 | G6: L - BM | H6: 23000 | I6: =H6-D6 -> 14500 | K6: 5 | L6: ANKOLE THANDA | M6: 9999
B7: 6 | C7: U - AM | D7: 9000 | F7: 6 | G7: U - AM | H7: 24000 | I7: =H7-D7 -> 15000 | K7: 6 | L7: AUTO NAGAR | M7: 5000
B8: 7 | C8: U - AS | D8: 9000 | F8: 7 | G8: U - AS | H8: 24000 | I8: =H8-D8 -> 15000 | K8: 7 | L8: AZAM GUNJ | M8: 5000
B9: 8 | C9: U - BM | D9: 9000 | F9: 8 | G9: U - BM | H9: 24000 | I9: =H9-D9 -> 15000 | K9: 8 | L9: BANDARPALLY | M9: 6000
B10: 9 | C10: 1 - AM | D10: 9500 | F10: 9 | G10: 1 - AM | H10: 25000 | I10: =H10-D10 -> 15500 | K10: 9 | L10: BANSWADA | M10: 9999
B11: 10 | C11: 1 - AS | D11: 9500 | F11: 10 | G11: 1 - AS | H11: 25000 | I11: =H11-D11 -> 15500 | K11: 10 | L11: BARDIPUR | M11: 7000
B12: 11 | C12: 1 - BM | D12: 9500 | F12: 11 | G12: 1 - BM | H12: 25000 | I12: =H12-D12 -> 15500 | K12: 11 | L12: BELLAL | M12: 5000
B13: 12 | C13: 2 - AM | D13: 10000 | F13: 12 | G13: 2 - AM | H13: 26000 | I13: =H13-D13 -> 16000 | K13: 12 | L13: BHULAXMI CAMP | M13: 7000
... B35: 34 | C35: 10 - BS | D35: 25000 | F35: 34 | G35: 10 - BS | H35: 47000 | I35: =H35-D35 -> 22000 | K35: 34 | L35: KAITHI THANDA | M35: 9999
K36: 35 | L36: KALDURKI | M36: 7000
K37: 36 | L37: KANDAKURTHI | M37: 8000
K38: 37 | L38: KARAKWADI | M38: 9999
K39: 38 | L39: KHANDGAON | M39: 9999
K40: 39 | L40: KOLOOR, THANUR. | M40: 9999
K41: 40 | L41: KOLUR | M41: 9999
K42: 41 | L42: KONDAPUR | M42: 9999
K43: 42 | L43: KOPPARGA | M43: 8000
K44: 43 | L44: KOPPARTHI CAMP | M44: 7000
K45: 44 | L45: KUMMANPALLY | M45: 7000
K46: 45 | L46: L.B.S. NAGAR | M46: 5000
K47: 46 | L47: LABDI, THANUR. | M47: 9999
... K102: 101 | L102: Brahmanpally | M102: 5000

Sheet Daily Fees Entry
A1: S.N. | B1: Date | C1: Receipt Number | D1: Adm | E1: Fees Type | F1: Fees Amount | G1: x | H1: Student Name | I1: Class | J1: Father Name | K1: Address | L1: Cell | M1: x | N1: Not Found Details
A2: 1 | B2: 44724 | C2: 1 | D2: 3082 | E2: School Fees | F2: 15000 | H2: =IF(TRIM(D2)="","",IFERROR(INDEX('Student Master'!C:C,MATCH(D2,'Student Master'!B:B,0)),"Not Found")) -> S. ARUN | I2: =IF(TRIM(D2)="","",IFERROR(INDEX('Student Master'!D:D,MATCH(D2,'Student Master'!B:B,0)),"Not Found")) -> 10 - AS | J2: =IF(TRIM(D2)="","",IFERROR(INDEX('Student Master'!H:H,MATCH(D2,'Student Master'!B:B,0)),"Not Found")) -> GANGARAM | K2: =IF(TRIM(D2)="","",IFERROR(INDEX('Student Master'!N:N,MATCH(D2,'Student Master'!B:B,0)),"Not Found")) -> BARDIPUR | L2: =IF(TRIM(D2)="","",IFERROR(INDEX('Student Master'!L:L,MATCH(D2,'Student Master'!B:B,0)),"Not Found")) -> 9133894901
A3: =A2+1 -> 2 | B3: 44724 | C3: 2 | D3: 4572 | E3: School Fees | F3: 3000 | H3: =IF(TRIM(D3)="","",IFERROR(INDEX('Student Master'!C:C,MATCH(D3,'Student Master'!B:B,0)),"Not Found")) -> B.Madhu Varshini | I3: =IF(TRIM(D3)="","",IFERROR(INDEX('Student Master'!D:D,MATCH(D3,'Student Master'!B:B,0)),"Not Found")) -> L - AM | J3: =IF(TRIM(D3)="","",IFERROR(INDEX('Student Master'!H:H,MATCH(D3,'Student Master'!B:B,0)),"Not Found")) -> Laxman | K3: =IF(TRIM(D3)="","",IFERROR(INDEX('Student Master'!N:N,MATCH(D3,'Student Master'!B:B,0)),"Not Found")) -> Old Salampad | L3: =IF(TRIM(D3)="","",IFERROR(INDEX('Student Master'!L:L,MATCH(D3,'Student Master'!B:B,0)),"Not Found")) -> 9553219616
A4: =A3+1 -> 3 | B4: 44725 | C4: 3 | D4: 4765 | E4: School Fees | F4: 1000 | H4: =IF(TRIM(D4)="","",IFERROR(INDEX('Student Master'!C:C,MATCH(D4,'Student Master'!B:B,0)),"Not Found")) -> B.ADARSH | I4: =IF(TRIM(D4)="","",IFERROR(INDEX('Student Master'!D:D,MATCH(D4,'Student Master'!B:B,0)),"Not Found")) -> U - AM | J4: =IF(TRIM(D4)="","",IFERROR(INDEX('Student Master'!H:H,MATCH(D4,'Student Master'!B:B,0)),"Not Found")) -> SANTHOSH | K4: =IF(TRIM(D4)="","",IFERROR(INDEX('Student Master'!N:N,MATCH(D4,'Student Master'!B:B,0)),"Not Found")) -> Hangarga | L4: =IF(TRIM(D4)="","",IFERROR(INDEX('Student Master'!L:L,MATCH(D4,'Student Master'!B:B,0)),"Not Found")) -> 8688174705
A5: =A4+1 -> 4 | B5: 44725 | C5: 4 | D5: 4575 | E5: School Fees | F5: 1000 | H5: =IF(TRIM(D5)="","",IFERROR(INDEX('Student Master'!C:C,MATCH(D5,'Student Master'!B:B,0)),"Not Found")) -> B.SHIVA CHARAN | I5: =IF(TRIM(D5)="","",IFERROR(INDEX('Student Master'!D:D,MATCH(D5,'Student Master'!B:B,0)),"Not Found")) -> 1 - BM | J5: =IF(TRIM(D5)="","",IFERROR(INDEX('Student Master'!H:H,MATCH(D5,'Student Master'!B:B,0)),"Not Found")) -> SANTHOSH | K5: =IF(TRIM(D5)="","",IFERROR(INDEX('Student Master'!N:N,MATCH(D5,'Student Master'!B:B,0)),"Not Found")) -> Hangarga | L5: =IF(TRIM(D5)="","",IFERROR(INDEX('Student Master'!L:L,MATCH(D5,'Student Master'!B:B,0)),"Not Found")) -> 8688174705
A6: =A5+1 -> 5 | B6: 44725 | C6: 5 | D6: 4578 | E6: School Fees | F6: 500 | H6: =IF(TRIM(D6)="","",IFERROR(INDEX('Student Master'!C:C,MATCH(D6,'Student Master'!B:B,0)),"Not Found")) -> S.SRAVANI | I6: =IF(TRIM(D6)="","",IFERROR(INDEX('Student Master'!D:D,MATCH(D6,'Student Master'!B:B,0)),"Not Found")) -> 7 - AS | J6: =IF(TRIM(D6)="","",IFERROR(INDEX('Student Master'!H:H,MATCH(D6,'Student Master'!B:B,0)),"Not Found")) -> S. LAXMAN | K6: =IF(TRIM(D6)="","",IFERROR(INDEX('Student Master'!N:N,MATCH(D6,'Student Master'!B:B,0)),"Not Found")) -> Kandakurthi | L6: =IF(TRIM(D6)="","",IFERROR(INDEX('Student Master'!L:L,MATCH(D6,'Student Master'!B:B,0)),"Not Found")) -> 6305389541
A7: =A6+1 -> 6 | B7: 44727 | C7: 6 | D7: 4442 | E7: School Fees | F7: 3500 | H7: =IF(TRIM(D7)="","",IFERROR(INDEX('Student Master'!C:C,MATCH(D7,'Student Master'!B:B,0)),"Not Found")) -> MD. MIRZA ABBU BAQAR | I7: =IF(TRIM(D7)="","",IFERROR(INDEX('Student Master'!D:D,MATCH(D7,'Student Master'!B:B,0)),"Not Found")) -> 1 - BM | J7: =IF(TRIM(D7)="","",IFERROR(INDEX('Student Master'!H:H,MATCH(D7,'Student Master'!B:B,0)),"Not Found")) -> MIRZA AZMATH BAIG | K7: =IF(TRIM(D7)="","",IFERROR(INDEX('Student Master'!N:N,MATCH(D7,'Student Master'!B:B,0)),"Not Found")) -> KOPPARGA | L7: =IF(TRIM(D7)="","",IFERROR(INDEX('Student Master'!L:L,MATCH(D7,'Student Master'!B:B,0)),"Not Found")) -> 7569194416
A8: =A7+1 -> 7 | B8: 44728 | C8: 7 | D8: 4775 | E8: School Fees | F8: 2000 | H8: =IF(TRIM(D8)="","",IFERROR(INDEX('Student Master'!C:C,MATCH(D8,'Student Master'!B:B,0)),"Not Found")) -> G.SOURAB | I8: =IF(TRIM(D8)="","",IFERROR(INDEX('Student Master'!D:D,MATCH(D8,'Student Master'!B:B,0)),"Not Found")) -> 2 - AS | J8: =IF(TRIM(D8)="","",IFERROR(INDEX('Student Master'!H:H,MATCH(D8,'Student Master'!B:B,0)),"Not Found")) -> G.NARESH | K8: =IF(TRIM(D8)="","",IFERROR(INDEX('Student Master'!N:N,MATCH(D8,'Student Master'!B:B,0)),"Not Found")) -> Papermill, Renjal | L8: =IF(TRIM(D8)="","",IFERROR(INDEX('Student Master'!L:L,MATCH(D8,'Student Master'!B:B,0)),"Not Found")) -> 9347189684
A9: =A8+1 -> 8 | B9: 44728 | C9: 8 | D9: 4774 | E9: School Fees | F9: 3000 | H9: =IF(TRIM(D9)="","",IFERROR(INDEX('Student Master'!C:C,MATCH(D9,'Student Master'!B:B,0)),"Not Found")) -> G. SAKSHI | I9: =IF(TRIM(D9)="","",IFERROR(INDEX('Student Master'!D:D,MATCH(D9,'Student Master'!B:B,0)),"Not Found")) -> 9 - AS | J9: =IF(TRIM(D9)="","",IFERROR(INDEX('Student Master'!H:H,MATCH(D9,'Student Master'!B:B,0)),"Not Found")) -> G.NARESH | K9: =IF(TRIM(D9)="","",IFERROR(INDEX('Student Master'!N:N,MATCH(D9,'Student Master'!B:B,0)),"Not Found")) -> Papermill, Renjal | L9: =IF(TRIM(D9)="","",IFERROR(INDEX('Student Master'!L:L,MATCH(D9,'Student Master'!B:B,0)),"Not Found")) -> 9347189684
A10: =A9+1 -> 9 | B10: 44728 | C10: 9 | D10: 4681 | E10: School Fees | F10: 1500 | H10: =IF(TRIM(D10)="","",IFERROR(INDEX('Student Master'!C:C,MATCH(D10,'Student Master'!B:B,0)),"Not Found")) -> SHAZIA GAZALA MAHEBUB | I10: =IF(TRIM(D10)="","",IFERROR(INDEX('Student Master'!D:D,MATCH(D10,'Student Master'!B:B,0)),"Not Found")) -> 2 - AS | J10: =IF(TRIM(D10)="","",IFERROR(INDEX('Student Master'!H:H,MATCH(D10,'Student Master'!B:B,0)),"Not Found")) -> SHAIK MAHABOOB | K10: =IF(TRIM(D10)="","",IFERROR(INDEX('Student Master'!N:N,MATCH(D10,'Student Master'!B:B,0)),"Not Found")) -> Azam Gunj | L10: =IF(TRIM(D10)="","",IFERROR(INDEX('Student Master'!L:L,MATCH(D10,'Student Master'!B:B,0)),"Not Found")) -> 9922696237
A11: =A10+1 -> 10 | B11: 44728 | C11: 10 | D11: 4683 | E11: School Fees | F11: 1500 | H11: =IF(TRIM(D11)="","",IFERROR(INDEX('Student Master'!C:C,MATCH(D11,'Student Master'!B:B,0)),"Not Found")) -> SHAIK TAMIN KOUSER MAHEBOOB | I11: =IF(TRIM(D11)="","",IFERROR(INDEX('Student Master'!D:D,MATCH(D11,'Student Master'!B:B,0)),"Not Found")) -> 6 - AS | J11: =IF(TRIM(D11)="","",IFERROR(INDEX('Student Master'!H:H,MATCH(D11,'Student Master'!B:B,0)),"Not Found")) -> SHAIK MAHEBOOB | K11: =IF(TRIM(D11)="","",IFERROR(INDEX('Student Master'!N:N,MATCH(D11,'Student Master'!B:B,0)),"Not Found")) -> Azam Gunj | L11: =IF(TRIM(D11)="","",IFERROR(INDEX('Student Master'!L:L,MATCH(D11,'Student Master'!B:B,0)),"Not Found")) -> 9922696237
A12: =A11+1 -> 11 | B12: 44730 | C12: 11 | D12: 4396 | E12: School Fees | F12: 2500 | H12: =IF(TRIM(D12)="","",IFERROR(INDEX('Student Master'!C:C,MATCH(D12,'Student Master'!B:B,0)),"Not Found")) -> CH. ABHINAV | I12: =IF(TRIM(D12)="","",IFERROR(INDEX('Student Master'!D:D,MATCH(D12,'Student Master'!B:B,0)),"Not Found")) -> L - AM | J12: =IF(TRIM(D12)="","",IFERROR(INDEX('Student Master'!H:H,MATCH(D12,'Student Master'!B:B,0)),"Not Found")) -> KRANTHI KUMAR | K12: =IF(TRIM(D12)="","",IFERROR(INDEX('Student Master'!N:N,MATCH(D12,'Student Master'!B:B,0)),"Not Found")) -> SHARBATHI CANAL | L12: =IF(TRIM(D12)="","",IFERROR(INDEX('Student Master'!L:L,MATCH(D12,'Student Master'!B:B,0)),"Not Found")) -> 9666690403
A13: =A12+1 -> 12 | B13: 44732 | C13: 12 | D13: 4406 | E13: School Fees | F13: 5000 | H13: =IF(TRIM(D13)="","",IFERROR(INDEX('Student Master'!C:C,MATCH(D13,'Student Master'!B:B,0)),"Not Found")) -> G. MOKSHITHA REDDY | I13: =IF(TRIM(D13)="","",IFERROR(INDEX('Student Master'!D:D,MATCH(D13,'Student Master'!B:B,0)),"Not Found")) -> U - BM | J13: =IF(TRIM(D13)="","",IFERROR(INDEX('Student Master'!H:H,MATCH(D13,'Student Master'!B:B,0)),"Not Found")) -> SUDHAKAR REDDY | K13: =IF(TRIM(D13)="","",IFERROR(INDEX('Student Master'!N:N,MATCH(D13,'Student Master'!B:B,0)),"Not Found")) -> BHULAXMI CAMP | L13: =IF(TRIM(D13)="","",IFERROR(INDEX('Student Master'!L:L,MATCH(D13,'Student Master'!B:B,0)),"Not Found")) -> 9640506086
A14: =A13+1 -> 13 | B14: 44732 | C14: 13 | D14: 4324 | E14: School Fees | F14: 5000 | H14: =IF(TRIM(D14)="","",IFERROR(INDEX('Student Master'!C:C,MATCH(D14,'Student Master'!B:B,0)),"Not Found")) -> G. PARINITHI REDDY | I14: =IF(TRIM(D14)="","",IFERROR(INDEX('Student Master'!D:D,MATCH(D14,'Student Master'!B:B,0)),"Not Found")) -> 1 - BM | J14: =IF(TRIM(D14)="","",IFERROR(INDEX('Student Master'!H:H,MATCH(D14,'Student Master'!B:B,0)),"Not Found")) -> G. SUDHAKAR REDDY | K14: =IF(TRIM(D14)="","",IFERROR(INDEX('Student Master'!N:N,MATCH(D14,'Student Master'!B:B,0)),"Not Found")) -> BHULAXMI CAMP | L14: =IF(TRIM(D14)="","",IFERROR(INDEX('Student Master'!L:L,MATCH(D14,'Student Master'!B:B,0)),"Not Found")) -> 9640506086
... A44: =A43+1 -> 43 | B44: 44769 | C44: 43 | D44: 4293 | E44: School Fees | F44: 5000 | H44: =IF(TRIM(D44)="","",IFERROR(INDEX('Student Master'!C:C,MATCH(D44,'Student Master'!B:B,0)),"Not Found")) -> V. SHANMUKA SREE | I44: =IF(TRIM(D44)="","",IFERROR(INDEX('Student Master'!D:D,MATCH(D44,'Student Master'!B:B,0)),"Not Found")) -> 2 - AM | J44: =IF(TRIM(D44)="","",IFERROR(INDEX('Student Master'!H:H,MATCH(D44,'Student Master'!B:B,0)),"Not Found")) -> V. RAVINDHAR REDDY | K44: =IF(TRIM(D44)="","",IFERROR(INDEX('Student Master'!N:N,MATCH(D44,'Student Master'!B:B,0)),"Not Found")) -> SALOORA CAMP | L44: =IF(TRIM(D44)="","",IFERROR(INDEX('Student Master'!L:L,MATCH(D44,'Student Master'!B:B,0)),"Not Found")) -> 6300626880
A45: =A44+1 -> 44 | C45: 44 | D45: CANCELLED | E45: School Fees | H45: =IF(TRIM(D45)="","",IFERROR(INDEX('Student Master'!C:C,MATCH(D45,'Student Master'!B:B,0)),"Not Found")) -> Not Found | I45: =IF(TRIM(D45)="","",IFERROR(INDEX('Student Master'!D:D,MATCH(D45,'Student Master'!B:B,0)),"Not Found")) -> Not Found | J45: =IF(TRIM(D45)="","",IFERROR(INDEX('Student Master'!H:H,MATCH(D45,'Student Master'!B:B,0)),"Not Found")) -> Not Found | K45: =IF(TRIM(D45)="","",IFERROR(INDEX('Student Master'!N:N,MATCH(D45,'Student Master'!B:B,0)),"Not Found")) -> Not Found | L45: =IF(TRIM(D45)="","",IFERROR(INDEX('Student Master'!L:L,MATCH(D45,'Student Master'!B:B,0)),"Not Found")) -> Not Found | N45: CANCELLED
A46: =A45+1 -> 45 | B46: 44769 | C46: 45 | D46: 2787 | E46: School Fees | F46: 10000 | H46: =IF(TRIM(D46)="","",IFERROR(INDEX('Student Master'!C:C,MATCH(D46,'Student Master'!B:B,0)),"Not Found")) -> S. MANI TEJA | I46: =IF(TRIM(D46)="","",IFERROR(INDEX('Student Master'!D:D,MATCH(D46,'Student Master'!B:B,0)),"Not Found")) -> 8 - AM | J46: =IF(TRIM(D46)="","",IFERROR(INDEX('Student Master'!H:H,MATCH(D46,'Student Master'!B:B,0)),"Not Found")) -> RAVI | K46: =IF(TRIM(D46)="","",IFERROR(INDEX('Student Master'!N:N,MATCH(D46,'Student Master'!B:B,0)),"Not Found")) -> YEDAPALLY | L46: =IF(TRIM(D46)="","",IFERROR(INDEX('Student Master'!L:L,MATCH(D46,'Student Master'!B:B,0)),"Not Found")) -> 9491742709
A47: =A46+1 -> 46 | B47: 44769 | C47: 46 | D47: 3804 | E47: School Fees | F47: 10000 | H47: =IF(TRIM(D47)="","",IFERROR(INDEX('Student Master'!C:C,MATCH(D47,'Student Master'!B:B,0)),"Not Found")) -> S. SRIKAR | I47: =IF(TRIM(D47)="","",IFERROR(INDEX('Student Master'!D:D,MATCH(D47,'Student Master'!B:B,0)),"Not Found")) -> 4 - AM | J47: =IF(TRIM(D47)="","",IFERROR(INDEX('Student Master'!H:H,MATCH(D47,'Student Master'!B:B,0)),"Not Found")) -> RAVI | K47: =IF(TRIM(D47)="","",IFERROR(INDEX('Student Master'!N:N,MATCH(D47,'Student Master'!B:B,0)),"Not Found")) -> YEDAPALLY | L47: =IF(TRIM(D47)="","",IFERROR(INDEX('Student Master'!L:L,MATCH(D47,'Student Master'!B:B,0)),"Not Found")) -> 9491742709
A48: =A47+1 -> 47 | B48: 44769 | C48: 47 | D48: X124 | E48: School Fees | F48: 1500 | H48: =IF(TRIM(D48)="","",IFERROR(INDEX('Student Master'!C:C,MATCH(D48,'Student Master'!B:B,0)),"Not Found")) -> K. ANJANA SOWMYA | I48: =IF(TRIM(D48)="","",IFERROR(INDEX('Student Master'!D:D,MATCH(D48,'Student Master'!B:B,0)),"Not Found")) -> 2 - BM | J48: =IF(TRIM(D48)="","",IFERROR(INDEX('Student Master'!H:H,MATCH(D48,'Student Master'!B:B,0)),"Not Found")) -> K. CHINNA GANGARAM | K48: =IF(TRIM(D48)="","",IFERROR(INDEX('Student Master'!N:N,MATCH(D48,'Student Master'!B:B,0)),"Not Found")) -> KUMMANPALLY | L48: =IF(TRIM(D48)="","",IFERROR(INDEX('Student Master'!L:L,MATCH(D48,'Student Master'!B:B,0)),"Not Found")) -> 9640614462
A49: =A48+1 -> 48 | B49: 44769 | C49: 48 | D49: 4452 | E49: School Fees | F49: 1500 | H49: =IF(TRIM(D49)="","",IFERROR(INDEX('Student Master'!C:C,MATCH(D49,'Student Master'!B:B,0)),"Not Found")) -> K. SWATHI | I49: =IF(TRIM(D49)="","",IFERROR(INDEX('Student Master'!D:D,MATCH(D49,'Student Master'!B:B,0)),"Not Found")) -> U - AM | J49: =IF(TRIM(D49)="","",IFERROR(INDEX('Student Master'!H:H,MATCH(D49,'Student Master'!B:B,0)),"Not Found")) -> CHINNA GANGARAM | K49: =IF(TRIM(D49)="","",IFERROR(INDEX('Student Master'!N:N,MATCH(D49,'Student Master'!B:B,0)),"Not Found")) -> KUMMANPALLY | L49: =IF(TRIM(D49)="","",IFERROR(INDEX('Student Master'!L:L,MATCH(D49,'Student Master'!B:B,0)),"Not Found")) -> 9640614462
A50: =A49+1 -> 49 | B50: 44769 | C50: 49 | D50: 4626 | E50: School Fees | F50: 2000 | H50: =IF(TRIM(D50)="","",IFERROR(INDEX('Student Master'!C:C,MATCH(D50,'Student Master'!B:B,0)),"Not Found")) -> G.Srujan | I50: =IF(TRIM(D50)="","",IFERROR(INDEX('Student Master'!D:D,MATCH(D50,'Student Master'!B:B,0)),"Not Found")) -> L - AM | J50: =IF(TRIM(D50)="","",IFERROR(INDEX('Student Master'!H:H,MATCH(D50,'Student Master'!B:B,0)),"Not Found")) -> Jayram | K50: =IF(TRIM(D50)="","",IFERROR(INDEX('Student Master'!N:N,MATCH(D50,'Student Master'!B:B,0)),"Not Found")) -> PANTAKHURD OLD | L50: =IF(TRIM(D50)="","",IFERROR(INDEX('Student Master'!L:L,MATCH(D50,'Student Master'!B:B,0)),"Not Found")) -> 9346062752
A51: =A50+1 -> 50 | B51: 44769 | C51: 50 | D51: 3980 | E51: School Fees | F51: 4500 | H51: =IF(TRIM(D51)="","",IFERROR(INDEX('Student Master'!C:C,MATCH(D51,'Student Master'!B:B,0)),"Not Found")) -> K. DEEKSHITHA REDDY | I51: =IF(TRIM(D51)="","",IFERROR(INDEX('Student Master'!D:D,MATCH(D51,'Student Master'!B:B,0)),"Not Found")) -> 3 - BM | J51: =IF(TRIM(D51)="","",IFERROR(INDEX('Student Master'!H:H,MATCH(D51,'Student Master'!B:B,0)),"Not Found")) -> K. SHIVALINGA REDDY | K51: =IF(TRIM(D51)="","",IFERROR(INDEX('Student Master'!N:N,MATCH(D51,'Student Master'!B:B,0)),"Not Found")) -> SALAMPAD | L51: =IF(TRIM(D51)="","",IFERROR(INDEX('Student Master'!L:L,MATCH(D51,'Student Master'!B:B,0)),"Not Found")) -> 9666793818
A52: =A51+1 -> 51 | B52: 44769 | C52: 51 | D52: 2956 | E52: School Fees | F52: 6000 | H52: =IF(TRIM(D52)="","",IFERROR(INDEX('Student Master'!C:C,MATCH(D52,'Student Master'!B:B,0)),"Not Found")) -> K. LAHARI | I52: =IF(TRIM(D52)="","",IFERROR(INDEX('Student Master'!D:D,MATCH(D52,'Student Master'!B:B,0)),"Not Found")) -> 7 - AM | J52: =IF(TRIM(D52)="","",IFERROR(INDEX('Student Master'!H:H,MATCH(D52,'Student Master'!B:B,0)),"Not Found")) -> SHIVA LINGA REDDY | K52: =IF(TRIM(D52)="","",IFERROR(INDEX('Student Master'!N:N,MATCH(D52,'Student Master'!B:B,0)),"Not Found")) -> SALAMPAD | L52: =IF(TRIM(D52)="","",IFERROR(INDEX('Student Master'!L:L,MATCH(D52,'Student Master'!B:B,0)),"Not Found")) -> 9666793818
A53: =A52+1 -> 52 | B53: 44769 | C53: 52 | D53: 3038 | E53: School Fees | F53: 6000 | H53: =IF(TRIM(D53)="","",IFERROR(INDEX('Student Master'!C:C,MATCH(D53,'Student Master'!B:B,0)),"Not Found")) -> K. MANOGNA | I53: =IF(TRIM(D53)="","",IFERROR(INDEX('Student Master'!D:D,MATCH(D53,'Student Master'!B:B,0)),"Not Found")) -> 7 - AM | J53: =IF(TRIM(D53)="","",IFERROR(INDEX('Student Master'!H:H,MATCH(D53,'Student Master'!B:B,0)),"Not Found")) -> KISHORE KUMAR REDDY | K53: =IF(TRIM(D53)="","",IFERROR(INDEX('Student Master'!N:N,MATCH(D53,'Student Master'!B:B,0)),"Not Found")) -> SALAMPAD | L53: =IF(TRIM(D53)="","",IFERROR(INDEX('Student Master'!L:L,MATCH(D53,'Student Master'!B:B,0)),"Not Found")) -> 8374952490
A54: =A53+1 -> 53 | B54: 44769 | C54: 53 | D54: 4386 | E54: School Fees | F54: 3000 | H54: =IF(TRIM(D54)="","",IFERROR(INDEX('Student Master'!C:C,MATCH(D54,'Student Master'!B:B,0)),"Not Found")) -> R. NANDINI | I54: =IF(TRIM(D54)="","",IFERROR(INDEX('Student Master'!D:D,MATCH(D54,'Student Master'!B:B,0)),"Not Found")) -> 9 - AM | J54: =IF(TRIM(D54)="","",IFERROR(INDEX('Student Master'!H:H,MATCH(D54,'Student Master'!B:B,0)),"Not Found")) -> PRAKASAM | K54: =IF(TRIM(D54)="","",IFERROR(INDEX('Student Master'!N:N,MATCH(D54,'Student Master'!B:B,0)),"Not Found")) -> KOPPARTHI CAMP | L54: =IF(TRIM(D54)="","",IFERROR(INDEX('Student Master'!L:L,MATCH(D54,'Student Master'!B:B,0)),"Not Found")) -> 8639551032
A55: =A54+1 -> 54 | B55: 44770 | C55: 54 | D55: 3990 | E55: School Fees | F55: 1000 | H55: =IF(TRIM(D55)="","",IFERROR(INDEX('Student Master'!C:C,MATCH(D55,'Student Master'!B:B,0)),"Not Found")) -> ZEENATH ALSHA | I55: =IF(TRIM(D55)="","",IFERROR(INDEX('Student Master'!D:D,MATCH(D55,'Student Master'!B:B,0)),"Not Found")) -> 3 - BM | J55: =IF(TRIM(D55)="","",IFERROR(INDEX('Student Master'!H:H,MATCH(D55,'Student Master'!B:B,0)),"Not Found")) -> SHAIK AMEER QUSRO | K55: =IF(TRIM(D55)="","",IFERROR(INDEX('Student Master'!N:N,MATCH(D55,'Student Master'!B:B,0)),"Not Found")) -> SHARBATHI CANAL | L55: =IF(TRIM(D55)="","",IFERROR(INDEX('Student Master'!L:L,MATCH(D55,'Student Master'!B:B,0)),"Not Found")) -> 9010273886
A56: =A55+1 -> 55 | B56: 44770 | C56: 55 | D56: 4486 | E56: School Fees | F56: 1000 | H56: =IF(TRIM(D56)="","",IFERROR(INDEX('Student Master'!C:C,MATCH(D56,'Student Master'!B:B,0)),"Not Found")) -> SK. DAWWOD | I56: =IF(TRIM(D56)="","",IFERROR(INDEX('Student Master'!D:D,MATCH(D56,'Student Master'!B:B,0)),"Not Found")) -> U - BM | J56: =IF(TRIM(D56)="","",IFERROR(INDEX('Student Master'!H:H,MATCH(D56,'Student Master'!B:B,0)),"Not Found")) -> AMEER KHUSRO | K56: =IF(TRIM(D56)="","",IFERROR(INDEX('Student Master'!N:N,MATCH(D56,'Student Master'!B:B,0)),"Not Found")) -> SHARBATHI CANAL | L56: =IF(TRIM(D56)="","",IFERROR(INDEX('Student Master'!L:L,MATCH(D56,'Student Master'!B:B,0)),"Not Found")) -> 9010273886
A57: =A56+1 -> 56 | B57: 44770 | C57: 56 | D57: 4290 | E57: School Fees | F57: 2000 | H57: =IF(TRIM(D57)="","",IFERROR(INDEX('Student Master'!C:C,MATCH(D57,'Student Master'!B:B,0)),"Not Found")) -> P. JASHWITHA | I57: =IF(TRIM(D57)="","",IFERROR(INDEX('Student Master'!D:D,MATCH(D57,'Student Master'!B:B,0)),"Not Found")) -> 2 - BM | J57: =IF(TRIM(D57)="","",IFERROR(INDEX('Student Master'!H:H,MATCH(D57,'Student Master'!B:B,0)),"Not Found")) -> P. NARASIMHA RAO | K57: =IF(TRIM(D57)="","",IFERROR(INDEX('Student Master'!N:N,MATCH(D57,'Student Master'!B:B,0)),"Not Found")) -> SALOORA CAMP | L57: =IF(TRIM(D57)="","",IFERROR(INDEX('Student Master'!L:L,MATCH(D57,'Student Master'!B:B,0)),"Not Found")) -> 9640268643
A58: =A57+1 -> 57 | B58: 44771 | C58: 57 | D58: 4238 | E58: School Fees | F58: 2500 | H58: =IF(TRIM(D58)="","",IFERROR(INDEX('Student Master'!C:C,MATCH(D58,'Student Master'!B:B,0)),"Not Found")) -> AAIRA FATHIMA | I58: =IF(TRIM(D58)="","",IFERROR(INDEX('Student Master'!D:D,MATCH(D58,'Student Master'!B:B,0)),"Not Found")) -> 2 - AM | J58: =IF(TRIM(D58)="","",IFERROR(INDEX('Student Master'!H:H,MATCH(D58,'Student Master'!B:B,0)),"Not Found")) -> MD. IYNUL HAQ | K58: =IF(TRIM(D58)="","",IFERROR(INDEX('Student Master'!N:N,MATCH(D58,'Student Master'!B:B,0)),"Not Found")) -> SHARBATHI CANAL | L58: =IF(TRIM(D58)="","",IFERROR(INDEX('Student Master'!L:L,MATCH(D58,'Student Master'!B:B,0)),"Not Found")) -> 9440964877
A59: =A58+1 -> 58 | B59: 44771 | C59: 58 | D59: 3823 | E59: School Fees | F59: 2500 | H59: =IF(TRIM(D59)="","",IFERROR(INDEX('Student Master'!C:C,MATCH(D59,'Student Master'!B:B,0)),"Not Found")) -> MD. SUFYAAN HASNAIN | I59: =IF(TRIM(D59)="","",IFERROR(INDEX('Student Master'!D:D,MATCH(D59,'Student Master'!B:B,0)),"Not Found")) -> 4 - BM | J59: =IF(TRIM(D59)="","",IFERROR(INDEX('Student Master'!H:H,MATCH(D59,'Student Master'!B:B,0)),"Not Found")) -> IYNUL HAQ | K59: =IF(TRIM(D59)="","",IFERROR(INDEX('Student Master'!N:N,MATCH(D59,'Student Master'!B:B,0)),"Not Found")) -> SHARBATHI CANAL | L59: =IF(TRIM(D59)="","",IFERROR(INDEX('Student Master'!L:L,MATCH(D59,'Student Master'!B:B,0)),"Not Found")) -> 9440964877
A60: =A59+1 -> 59 | B60: 44771 | C60: 59 | D60: 3565 | E60: School Fees | F60: 2500 | H60: =IF(TRIM(D60)="","",IFERROR(INDEX('Student Master'!C:C,MATCH(D60,'Student Master'!B:B,0)),"Not Found")) -> MEHVISH FATHIMA | I60: =IF(TRIM(D60)="","",IFERROR(INDEX('Student Master'!D:D,MATCH(D60,'Student Master'!B:B,0)),"Not Found")) -> 5 - BM | J60: =IF(TRIM(D60)="","",IFERROR(INDEX('Student Master'!H:H,MATCH(D60,'Student Master'!B:B,0)),"Not Found")) -> AINUL HAQUE | K60: =IF(TRIM(D60)="","",IFERROR(INDEX('Student Master'!N:N,MATCH(D60,'Student Master'!B:B,0)),"Not Found")) -> SHARBATHI CANAL | L60: =IF(TRIM(D60)="","",IFERROR(INDEX('Student Master'!L:L,MATCH(D60,'Student Master'!B:B,0)),"Not Found")) -> 9440964877
... A144: =A143+1 -> 143 | B144: 44807 | C144: 143 | D144: 4452 | E144: School Fees | F144: 5500 | H144: =IF(TRIM(D144)="","",IFERROR(INDEX('Student Master'!C:C,MATCH(D144,'Student Master'!B:B,0)),"Not Found")) -> K. SWATHI | I144: =IF(TRIM(D144)="","",IFERROR(INDEX('Student Master'!D:D,MATCH(D144,'Student Master'!B:B,0)),"Not Found")) -> U - AM | J144: =IF(TRIM(D144)="","",IFERROR(INDEX('Student Master'!H:H,MATCH(D144,'Student Master'!B:B,0)),"Not Found")) -> CHINNA GANGARAM | K144: =IF(TRIM(D144)="","",IFERROR(INDEX('Student Master'!N:N,MATCH(D144,'Student Master'!B:B,0)),"Not Found")) -> KUMMANPALLY | L144: =IF(TRIM(D144)="","",IFERROR(INDEX('Student Master'!L:L,MATCH(D144,'Student Master'!B:B,0)),"Not Found")) -> 9640614462
A145: =A144+1 -> 144 | B145: 44807 | C145: 144 | D145: x124 | E145: School Fees | F145: 5500 | H145: =IF(TRIM(D145)="","",IFERROR(INDEX('Student Master'!C:C,MATCH(D145,'Student Master'!B:B,0)),"Not Found")) -> K. ANJANA SOWMYA | I145: =IF(TRIM(D145)="","",IFERROR(INDEX('Student Master'!D:D,MATCH(D145,'Student Master'!B:B,0)),"Not Found")) -> 2 - BM | J145: =IF(TRIM(D145)="","",IFERROR(INDEX('Student Master'!H:H,MATCH(D145,'Student Master'!B:B,0)),"Not Found")) -> K. CHINNA GANGARAM | K145: =IF(TRIM(D145)="","",IFERROR(INDEX('Student Master'!N:N,MATCH(D145,'Student Master'!B:B,0)),"Not Found")) -> KUMMANPALLY | L145: =IF(TRIM(D145)="","",IFERROR(INDEX('Student Master'!L:L,MATCH(D145,'Student Master'!B:B,0)),"Not Found")) -> 9640614462
A146: =A145+1 -> 145 | B146: 44807 | C146: 145 | D146: 4195 | E146: School Fees | F146: 4000 | H146: =IF(TRIM(D146)="","",IFERROR(INDEX('Student Master'!C:C,MATCH(D146,'Student Master'!B:B,0)),"Not Found")) -> CH. TEJASVI | I146: =IF(TRIM(D146)="","",IFERROR(INDEX('Student Master'!D:D,MATCH(D146,'Student Master'!B:B,0)),"Not Found")) -> 2 - BM | J146: =IF(TRIM(D146)="","",IFERROR(INDEX('Student Master'!H:H,MATCH(D146,'Student Master'!B:B,0)),"Not Found")) -> CH. ANAND | K146: =IF(TRIM(D146)="","",IFERROR(INDEX('Student Master'!N:N,MATCH(D146,'Student Master'!B:B,0)),"Not Found")) -> PANTA CAMP | L146: =IF(TRIM(D146)="","",IFERROR(INDEX('Student Master'!L:L,MATCH(D146,'Student Master'!B:B,0)),"Not Found")) -> 9866673755
A147: =A146+1 -> 146 | B147: 44807 | C147: 146 | D147: 4501 | E147: School Fees | F147: 4000 | H147: =IF(TRIM(D147)="","",IFERROR(INDEX('Student Master'!C:C,MATCH(D147,'Student Master'!B:B,0)),"Not Found")) -> CH. AARTHI NAGA SAI | I147: =IF(TRIM(D147)="","",IFERROR(INDEX('Student Master'!D:D,MATCH(D147,'Student Master'!B:B,0)),"Not Found")) -> U - BM | J147: =IF(TRIM(D147)="","",IFERROR(INDEX('Student Master'!H:H,MATCH(D147,'Student Master'!B:B,0)),"Not Found")) -> ANAND | K147: =IF(TRIM(D147)="","",IFERROR(INDEX('Student Master'!N:N,MATCH(D147,'Student Master'!B:B,0)),"Not Found")) -> PANTAKHURD OLD | L147: =IF(TRIM(D147)="","",IFERROR(INDEX('Student Master'!L:L,MATCH(D147,'Student Master'!B:B,0)),"Not Found")) -> 9866673755
A148: =A147+1 -> 147 | B148: 44807 | C148: 147 | D148: 4633 | E148: School Fees | F148: 2000 | H148: =IF(TRIM(D148)="","",IFERROR(INDEX('Student Master'!C:C,MATCH(D148,'Student Master'!B:B,0)),"Not Found")) -> SHAIK MAVIYA | I148: =IF(TRIM(D148)="","",IFERROR(INDEX('Student Master'!D:D,MATCH(D148,'Student Master'!B:B,0)),"Not Found")) -> U - AM | J148: =IF(TRIM(D148)="","",IFERROR(INDEX('Student Master'!H:H,MATCH(D148,'Student Master'!B:B,0)),"Not Found")) -> MAQDOOM | K148: =IF(TRIM(D148)="","",IFERROR(INDEX('Student Master'!N:N,MATCH(D148,'Student Master'!B:B,0)),"Not Found")) -> Bodhan | L148: =IF(TRIM(D148)="","",IFERROR(INDEX('Student Master'!L:L,MATCH(D148,'Student Master'!B:B,0)),"Not Found")) -> 9963978223
A149: =A148+1 -> 148 | B149: 44807 | C149: 148 | D149: 4778 | E149: School Fees | F149: 5000 | H149: =IF(TRIM(D149)="","",IFERROR(INDEX('Student Master'!C:C,MATCH(D149,'Student Master'!B:B,0)),"Not Found")) -> CH. RAKSHITHA | I149: =IF(TRIM(D149)="","",IFERROR(INDEX('Student Master'!D:D,MATCH(D149,'Student Master'!B:B,0)),"Not Found")) -> 1 - AM | J149: =IF(TRIM(D149)="","",IFERROR(INDEX('Student Master'!H:H,MATCH(D149,'Student Master'!B:B,0)),"Not Found")) -> CH. RAJESH | K149: =IF(TRIM(D149)="","",IFERROR(INDEX('Student Master'!N:N,MATCH(D149,'Student Master'!B:B,0)),"Not Found")) -> JADI JAMALPUR | L149: =IF(TRIM(D149)="","",IFERROR(INDEX('Student Master'!L:L,MATCH(D149,'Student Master'!B:B,0)),"Not Found")) -> 9059051431
A150: =A149+1 -> 149 | B150: 44807 | C150: 149 | D150: 4444 | E150: School Fees | F150: 2000 | H150: =IF(TRIM(D150)="","",IFERROR(INDEX('Student Master'!C:C,MATCH(D150,'Student Master'!B:B,0)),"Not Found")) -> U. JASHITHA | I150: =IF(TRIM(D150)="","",IFERROR(INDEX('Student Master'!D:D,MATCH(D150,'Student Master'!B:B,0)),"Not Found")) -> L - AM | J150: =IF(TRIM(D150)="","",IFERROR(INDEX('Student Master'!H:H,MATCH(D150,'Student Master'!B:B,0)),"Not Found")) -> NAGANATH | K150: =IF(TRIM(D150)="","",IFERROR(INDEX('Student Master'!N:N,MATCH(D150,'Student Master'!B:B,0)),"Not Found")) -> L.B.S. NAGAR | L150: =IF(TRIM(D150)="","",IFERROR(INDEX('Student Master'!L:L,MATCH(D150,'Student Master'!B:B,0)),"Not Found")) -> 8179841092
A151: =A150+1 -> 150 | B151: 44807 | C151: 150 | D151: 4333 | E151: School Fees | F151: 2500 | H151: =IF(TRIM(D151)="","",IFERROR(INDEX('Student Master'!C:C,MATCH(D151,'Student Master'!B:B,0)),"Not Found")) -> SUBIYA FATHIMA | I151: =IF(TRIM(D151)="","",IFERROR(INDEX('Student Master'!D:D,MATCH(D151,'Student Master'!B:B,0)),"Not Found")) -> 1 - BM | J151: =IF(TRIM(D151)="","",IFERROR(INDEX('Student Master'!H:H,MATCH(D151,'Student Master'!B:B,0)),"Not Found")) -> ABDUL WAJID | K151: =IF(TRIM(D151)="","",IFERROR(INDEX('Student Master'!N:N,MATCH(D151,'Student Master'!B:B,0)),"Not Found")) -> RAKASIPET | L151: =IF(TRIM(D151)="","",IFERROR(INDEX('Student Master'!L:L,MATCH(D151,'Student Master'!B:B,0)),"Not Found")) -> 7729803720
A152: =A151+1 -> 151 | B152: 44807 | C152: 151 | D152: 3819 | E152: School Fees | F152: 2500 | H152: =IF(TRIM(D152)="","",IFERROR(INDEX('Student Master'!C:C,MATCH(D152,'Student Master'!B:B,0)),"Not Found")) -> SK. ABDUL MALIK | I152: =IF(TRIM(D152)="","",IFERROR(INDEX('Student Master'!D:D,MATCH(D152,'Student Master'!B:B,0)),"Not Found")) -> 4 - BM | J152: =IF(TRIM(D152)="","",IFERROR(INDEX('Student Master'!H:H,MATCH(D152,'Student Master'!B:B,0)),"Not Found")) -> ABDUL WAJID | K152: =IF(TRIM(D152)="","",IFERROR(INDEX('Student Master'!N:N,MATCH(D152,'Student Master'!B:B,0)),"Not Found")) -> RAKASIPET | L152: =IF(TRIM(D152)="","",IFERROR(INDEX('Student Master'!L:L,MATCH(D152,'Student Master'!B:B,0)),"Not Found")) -> 7729803720
...

Sheet Agreements-New
A1: S.No | B1: Date | C1: Agreement Number | D1: Admission Number | E1: Agreement Fees - New | F1: x | G1: Total Fees | H1: School Fees | I1: Bus Fees | J1: Hostel Fees | K1: % | L1: x | M1: Student Name | N1: Class | O1: Father Name | P1: Address | Q1: Cell | AP1: x | AQ1: x | AR1: x
A2: 1 | B2: 44831 | C2: 1 | D2: 4148 | E2: 8000 | G2: =IF(TRIM(D2)="","",IFERROR(INDEX('Student Master'!AB:AB,MATCH(D2,'Student Master'!B:B,0)),"0")) -> 9500 | H2: =IF(TRIM(D2)="","",IFERROR(INDEX('Student Master'!AG:AG,MATCH(D2,'Student Master'!B:B,0)),"0")) -> 9500 | I2: =IF(TRIM(D2)="","",IFERROR(INDEX('Student Master'!AH:AH,MATCH(D2,'Student Master'!B:B,0)),"0")) -> 0 | J2: =IF(TRIM(D2)="","",IFERROR(INDEX('Student Master'!AI:AI,MATCH(D2,'Student Master'!B:B,0)),"0")) -> 0 | K2: =IF(TRIM(D2)="","",E2/G2) -> 0.84210526 | M2: =IF(TRIM(D2)="","",IFERROR(INDEX('Student Master'!C:C,MATCH(D2,'Student Master'!B:B,0)),"0")) -> MEER NOMAN ALI | N2: =IF(TRIM(D2)="","",IFERROR(INDEX('Student Master'!D:D,MATCH(D2,'Student Master'!B:B,0)),"0")) -> 1 - AM | O2: =IF(TRIM(D2)="","",IFERROR(INDEX('Student Master'!H:H,MATCH(D2,'Student Master'!B:B,0)),"0")) -> MEER KHADAR ALI | P2: =IF(TRIM(D2)="","",IFERROR(INDEX('Student Master'!N:N,MATCH(D2,'Student Master'!B:B,0)),"0")) -> SHARBATHI CANAL | Q2: =IF(TRIM(D2)="","",IFERROR(INDEX('Student Master'!L:L,MATCH(D2,'Student Master'!B:B,0)),"0")) -> 9010209080
A3: 2 | B3: 44831 | C3: 2 | D3: 4293 | E3: 13500 | G3: =IF(TRIM(D3)="","",IFERROR(INDEX('Student Master'!AB:AB,MATCH(D3,'Student Master'!B:B,0)),"0")) -> 16500 | H3: =IF(TRIM(D3)="","",IFERROR(INDEX('Student Master'!AG:AG,MATCH(D3,'Student Master'!B:B,0)),"0")) -> 10000 | I3: =IF(TRIM(D3)="","",IFERROR(INDEX('Student Master'!AH:AH,MATCH(D3,'Student Master'!B:B,0)),"0")) -> 6500 | J3: =IF(TRIM(D3)="","",IFERROR(INDEX('Student Master'!AI:AI,MATCH(D3,'Student Master'!B:B,0)),"0")) -> 0 | K3: =IF(TRIM(D3)="","",E3/G3) -> 0.81818182 | M3: =IF(TRIM(D3)="","",IFERROR(INDEX('Student Master'!C:C,MATCH(D3,'Student Master'!B:B,0)),"0")) -> V. SHANMUKA SREE | N3: =IF(TRIM(D3)="","",IFERROR(INDEX('Student Master'!D:D,MATCH(D3,'Student Master'!B:B,0)),"0")) -> 2 - AM | O3: =IF(TRIM(D3)="","",IFERROR(INDEX('Student Master'!H:H,MATCH(D3,'Student Master'!B:B,0)),"0")) -> V. RAVINDHAR REDDY | P3: =IF(TRIM(D3)="","",IFERROR(INDEX('Student Master'!N:N,MATCH(D3,'Student Master'!B:B,0)),"0")) -> SALOORA CAMP | Q3: =IF(TRIM(D3)="","",IFERROR(INDEX('Student Master'!L:L,MATCH(D3,'Student Master'!B:B,0)),"0")) -> 6300626880
A4: 3 | B4: 44833 | C4: 3 | D4: 4238 | E4: 7500 | G4: =IF(TRIM(D4)="","",IFERROR(INDEX('Student Master'!AB:AB,MATCH(D4,'Student Master'!B:B,0)),"0")) -> 10000 | H4: =IF(TRIM(D4)="","",IFERROR(INDEX('Student Master'!AG:AG,MATCH(D4,'Student Master'!B:B,0)),"0")) -> 10000 | I4: =IF(TRIM(D4)="","",IFERROR(INDEX('Student Master'!AH:AH,MATCH(D4,'Student Master'!B:B,0)),"0")) -> 0 | J4: =IF(TRIM(D4)="","",IFERROR(INDEX('Student Master'!AI:AI,MATCH(D4,'Student Master'!B:B,0)),"0")) -> 0 | K4: =IF(TRIM(D4)="","",E4/G4) -> 0.75 | M4: =IF(TRIM(D4)="","",IFERROR(INDEX('Student Master'!C:C,MATCH(D4,'Student Master'!B:B,0)),"0")) -> AAIRA FATHIMA | N4: =IF(TRIM(D4)="","",IFERROR(INDEX('Student Master'!D:D,MATCH(D4,'Student Master'!B:B,0)),"0")) -> 2 - AM | O4: =IF(TRIM(D4)="","",IFERROR(INDEX('Student Master'!H:H,MATCH(D4,'Student Master'!B:B,0)),"0")) -> MD. IYNUL HAQ | P4: =IF(TRIM(D4)="","",IFERROR(INDEX('Student Master'!N:N,MATCH(D4,'Student Master'!B:B,0)),"0")) -> SHARBATHI CANAL | Q4: =IF(TRIM(D4)="","",IFERROR(INDEX('Student Master'!L:L,MATCH(D4,'Student Master'!B:B,0)),"0")) -> 9440964877
A5: 4 | B5: 44833 | C5: 3 | D5: 3823 | E5: 9000 | G5: =IF(TRIM(D5)="","",IFERROR(INDEX('Student Master'!AB:AB,MATCH(D5,'Student Master'!B:B,0)),"0")) -> 11500 | H5: =IF(TRIM(D5)="","",IFERROR(INDEX('Student Master'!AG:AG,MATCH(D5,'Student Master'!B:B,0)),"0")) -> 11500 | I5: =IF(TRIM(D5)="","",IFERROR(INDEX('Student Master'!AH:AH,MATCH(D5,'Student Master'!B:B,0)),"0")) -> 0 | J5: =IF(TRIM(D5)="","",IFERROR(INDEX('Student Master'!AI:AI,MATCH(D5,'Student Master'!B:B,0)),"0")) -> 0 | K5: =IF(TRIM(D5)="","",E5/G5) -> 0.7826087 | M5: =IF(TRIM(D5)="","",IFERROR(INDEX('Student Master'!C:C,MATCH(D5,'Student Master'!B:B,0)),"0")) -> MD. SUFYAAN HASNAIN | N5: =IF(TRIM(D5)="","",IFERROR(INDEX('Student Master'!D:D,MATCH(D5,'Student Master'!B:B,0)),"0")) -> 4 - BM | O5: =IF(TRIM(D5)="","",IFERROR(INDEX('Student Master'!H:H,MATCH(D5,'Student Master'!B:B,0)),"0")) -> IYNUL HAQ | P5: =IF(TRIM(D5)="","",IFERROR(INDEX('Student Master'!N:N,MATCH(D5,'Student Master'!B:B,0)),"0")) -> SHARBATHI CANAL | Q5: =IF(TRIM(D5)="","",IFERROR(INDEX('Student Master'!L:L,MATCH(D5,'Student Master'!B:B,0)),"0")) -> 9440964877
A6: 5 | B6: 44833 | C6: 3 | D6: 3565 | E6: 11000 | G6: =IF(TRIM(D6)="","",IFERROR(INDEX('Student Master'!AB:AB,MATCH(D6,'Student Master'!B:B,0)),"0")) -> 12500 | H6: =IF(TRIM(D6)="","",IFERROR(INDEX('Student Master'!AG:AG,MATCH(D6,'Student Master'!B:B,0)),"0")) -> 12500 | I6: =IF(TRIM(D6)="","",IFERROR(INDEX('Student Master'!AH:AH,MATCH(D6,'Student Master'!B:B,0)),"0")) -> 0 | J6: =IF(TRIM(D6)="","",IFERROR(INDEX('Student Master'!AI:AI,MATCH(D6,'Student Master'!B:B,0)),"0")) -> 0 | K6: =IF(TRIM(D6)="","",E6/G6) -> 0.88 | M6: =IF(TRIM(D6)="","",IFERROR(INDEX('Student Master'!C:C,MATCH(D6,'Student Master'!B:B,0)),"0")) -> MEHVISH FATHIMA | N6: =IF(TRIM(D6)="","",IFERROR(INDEX('Student Master'!D:D,MATCH(D6,'Student Master'!B:B,0)),"0")) -> 5 - BM | O6: =IF(TRIM(D6)="","",IFERROR(INDEX('Student Master'!H:H,MATCH(D6,'Student Master'!B:B,0)),"0")) -> AINUL HAQUE | P6: =IF(TRIM(D6)="","",IFERROR(INDEX('Student Master'!N:N,MATCH(D6,'Student Master'!B:B,0)),"0")) -> SHARBATHI CANAL | Q6: =IF(TRIM(D6)="","",IFERROR(INDEX('Student Master'!L:L,MATCH(D6,'Student Master'!B:B,0)),"0")) -> 9440964877
A7: 6 | B7: 44833 | C7: 3 | D7: 4393 | E7: 6500 | G7: =IF(TRIM(D7)="","",IFERROR(INDEX('Student Master'!AB:AB,MATCH(D7,'Student Master'!B:B,0)),"0")) -> 9000 | H7: =IF(TRIM(D7)="","",IFERROR(INDEX('Student Master'!AG:AG,MATCH(D7,'Student Master'!B:B,0)),"0")) -> 9000 | I7: =IF(TRIM(D7)="","",IFERROR(INDEX('Student Master'!AH:AH,MATCH(D7,'Student Master'!B:B,0)),"0")) -> 0 | J7: =IF(TRIM(D7)="","",IFERROR(INDEX('Student Master'!AI:AI,MATCH(D7,'Student Master'!B:B,0)),"0")) -> 0 | K7: =IF(TRIM(D7)="","",E7/G7) -> 0.72222222 | M7: =IF(TRIM(D7)="","",IFERROR(INDEX('Student Master'!C:C,MATCH(D7,'Student Master'!B:B,0)),"0")) -> TUBA FATHIMA | N7: =IF(TRIM(D7)="","",IFERROR(INDEX('Student Master'!D:D,MATCH(D7,'Student Master'!B:B,0)),"0")) -> U - BM | O7: =IF(TRIM(D7)="","",IFERROR(INDEX('Student Master'!H:H,MATCH(D7,'Student Master'!B:B,0)),"0")) -> IYNUL HAQUE | P7: =IF(TRIM(D7)="","",IFERROR(INDEX('Student Master'!N:N,MATCH(D7,'Student Master'!B:B,0)),"0")) -> SHARBATHI CANAL | Q7: =IF(TRIM(D7)="","",IFERROR(INDEX('Student Master'!L:L,MATCH(D7,'Student Master'!B:B,0)),"0")) -> 9440964877
A8: 7 | B8: 44833 | C8: 4 | D8: 4144 | E8: 9000 | G8: =IF(TRIM(D8)="","",IFERROR(INDEX('Student Master'!AB:AB,MATCH(D8,'Student Master'!B:B,0)),"0")) -> 10000 | H8: =IF(TRIM(D8)="","",IFERROR(INDEX('Student Master'!AG:AG,MATCH(D8,'Student Master'!B:B,0)),"0")) -> 10000 | I8: =IF(TRIM(D8)="","",IFERROR(INDEX('Student Master'!AH:AH,MATCH(D8,'Student Master'!B:B,0)),"0")) -> 0 | J8: =IF(TRIM(D8)="","",IFERROR(INDEX('Student Master'!AI:AI,MATCH(D8,'Student Master'!B:B,0)),"0")) -> 0 | K8: =IF(TRIM(D8)="","",E8/G8) -> 0.9 | M8: =IF(TRIM(D8)="","",IFERROR(INDEX('Student Master'!C:C,MATCH(D8,'Student Master'!B:B,0)),"0")) -> T. ADITHYA | N8: =IF(TRIM(D8)="","",IFERROR(INDEX('Student Master'!D:D,MATCH(D8,'Student Master'!B:B,0)),"0")) -> 2 - AM | O8: =IF(TRIM(D8)="","",IFERROR(INDEX('Student Master'!H:H,MATCH(D8,'Student Master'!B:B,0)),"0")) -> ASHOK | P8: =IF(TRIM(D8)="","",IFERROR(INDEX('Student Master'!N:N,MATCH(D8,'Student Master'!B:B,0)),"0")) -> NEAR H.P.O. | Q8: =IF(TRIM(D8)="","",IFERROR(INDEX('Student Master'!L:L,MATCH(D8,'Student Master'!B:B,0)),"0")) -> 9963370315
A9: 8 | B9: 44833 | C9: 4 | D9: 4143 | E9: 8000 | G9: =IF(TRIM(D9)="","",IFERROR(INDEX('Student Master'!AB:AB,MATCH(D9,'Student Master'!B:B,0)),"0")) -> 9000 | H9: =IF(TRIM(D9)="","",IFERROR(INDEX('Student Master'!AG:AG,MATCH(D9,'Student Master'!B:B,0)),"0")) -> 9000 | I9: =IF(TRIM(D9)="","",IFERROR(INDEX('Student Master'!AH:AH,MATCH(D9,'Student Master'!B:B,0)),"0")) -> 0 | J9: =IF(TRIM(D9)="","",IFERROR(INDEX('Student Master'!AI:AI,MATCH(D9,'Student Master'!B:B,0)),"0")) -> 0 | K9: =IF(TRIM(D9)="","",E9/G9) -> 0.88888889 | M9: =IF(TRIM(D9)="","",IFERROR(INDEX('Student Master'!C:C,MATCH(D9,'Student Master'!B:B,0)),"0")) -> T. SAHASRA | N9: =IF(TRIM(D9)="","",IFERROR(INDEX('Student Master'!D:D,MATCH(D9,'Student Master'!B:B,0)),"0")) -> U - BM | O9: =IF(TRIM(D9)="","",IFERROR(INDEX('Student Master'!H:H,MATCH(D9,'Student Master'!B:B,0)),"0")) -> ASHOK | P9: =IF(TRIM(D9)="","",IFERROR(INDEX('Student Master'!N:N,MATCH(D9,'Student Master'!B:B,0)),"0")) -> NEAR H.P.O. | Q9: =IF(TRIM(D9)="","",IFERROR(INDEX('Student Master'!L:L,MATCH(D9,'Student Master'!B:B,0)),"0")) -> 9963370315
A10: 9 | B10: 44833 | C10: 5 | D10: 3408 | E10: 19000 | G10: =IF(TRIM(D10)="","",IFERROR(INDEX('Student Master'!AB:AB,MATCH(D10,'Student Master'!B:B,0)),"0")) -> 24000 | H10: =IF(TRIM(D10)="","",IFERROR(INDEX('Student Master'!AG:AG,MATCH(D10,'Student Master'!B:B,0)),"0")) -> 16000 | I10: =IF(TRIM(D10)="","",IFERROR(INDEX('Student Master'!AH:AH,MATCH(D10,'Student Master'!B:B,0)),"0")) -> 8000 | J10: =IF(TRIM(D10)="","",IFERROR(INDEX('Student Master'!AI:AI,MATCH(D10,'Student Master'!B:B,0)),"0")) -> 0 | K10: =IF(TRIM(D10)="","",E10/G10) -> 0.79166667 | M10: =IF(TRIM(D10)="","",IFERROR(INDEX('Student Master'!C:C,MATCH(D10,'Student Master'!B:B,0)),"0")) -> S. SHARATH KUMAR | N10: =IF(TRIM(D10)="","",IFERROR(INDEX('Student Master'!D:D,MATCH(D10,'Student Master'!B:B,0)),"0")) -> 7 - AM | O10: =IF(TRIM(D10)="","",IFERROR(INDEX('Student Master'!H:H,MATCH(D10,'Student Master'!B:B,0)),"0")) -> SURESH | P10: =IF(TRIM(D10)="","",IFERROR(INDEX('Student Master'!N:N,MATCH(D10,'Student Master'!B:B,0)),"0")) -> HANGARGA | Q10: =IF(TRIM(D10)="","",IFERROR(INDEX('Student Master'!L:L,MATCH(D10,'Student Master'!B:B,0)),"0")) -> 9618252975
A11: 10 | B11: 44833 | C11: 5 | D11: 4211 | E11: 13000 | G11: =IF(TRIM(D11)="","",IFERROR(INDEX('Student Master'!AB:AB,MATCH(D11,'Student Master'!B:B,0)),"0")) -> 18000 | H11: =IF(TRIM(D11)="","",IFERROR(INDEX('Student Master'!AG:AG,MATCH(D11,'Student Master'!B:B,0)),"0")) -> 10000 | I11: =IF(TRIM(D11)="","",IFERROR(INDEX('Student Master'!AH:AH,MATCH(D11,'Student Master'!B:B,0)),"0")) -> 8000 | J11: =IF(TRIM(D11)="","",IFERROR(INDEX('Student Master'!AI:AI,MATCH(D11,'Student Master'!B:B,0)),"0")) -> 0 | K11: =IF(TRIM(D11)="","",E11/G11) -> 0.72222222 | M11: =IF(TRIM(D11)="","",IFERROR(INDEX('Student Master'!C:C,MATCH(D11,'Student Master'!B:B,0)),"0")) -> S. SIDDHANTH KUMAR | N11: =IF(TRIM(D11)="","",IFERROR(INDEX('Student Master'!D:D,MATCH(D11,'Student Master'!B:B,0)),"0")) -> 2 - AM | O11: =IF(TRIM(D11)="","",IFERROR(INDEX('Student Master'!H:H,MATCH(D11,'Student Master'!B:B,0)),"0")) -> S. SURESH | P11: =IF(TRIM(D11)="","",IFERROR(INDEX('Student Master'!N:N,MATCH(D11,'Student Master'!B:B,0)),"0")) -> HANGARGA | Q11: =IF(TRIM(D11)="","",IFERROR(INDEX('Student Master'!L:L,MATCH(D11,'Student Master'!B:B,0)),"0")) -> 9618252975
A12: 11 | B12: 44834 | C12: 6 | D12: 3936 | E12: 25000 | G12: =IF(TRIM(D12)="","",IFERROR(INDEX('Student Master'!AB:AB,MATCH(D12,'Student Master'!B:B,0)),"0")) -> 27000 | H12: =IF(TRIM(D12)="","",IFERROR(INDEX('Student Master'!AG:AG,MATCH(D12,'Student Master'!B:B,0)),"0")) -> 20000 | I12: =IF(TRIM(D12)="","",IFERROR(INDEX('Student Master'!AH:AH,MATCH(D12,'Student Master'!B:B,0)),"0")) -> 7000 | J12: =IF(TRIM(D12)="","",IFERROR(INDEX('Student Master'!AI:AI,MATCH(D12,'Student Master'!B:B,0)),"0")) -> 0 | K12: =IF(TRIM(D12)="","",E12/G12) -> 0.92592593 | M12: =IF(TRIM(D12)="","",IFERROR(INDEX('Student Master'!C:C,MATCH(D12,'Student Master'!B:B,0)),"0")) -> A. AKSHITHA | N12: =IF(TRIM(D12)="","",IFERROR(INDEX('Student Master'!D:D,MATCH(D12,'Student Master'!B:B,0)),"0")) -> 9 - AM | O12: =IF(TRIM(D12)="","",IFERROR(INDEX('Student Master'!H:H,MATCH(D12,'Student Master'!B:B,0)),"0")) -> A. CHANDRAKANTH | P12: =IF(TRIM(D12)="","",IFERROR(INDEX('Student Master'!N:N,MATCH(D12,'Student Master'!B:B,0)),"0")) -> KUMMANPALLY | Q12: =IF(TRIM(D12)="","",IFERROR(INDEX('Student Master'!L:L,MATCH(D12,'Student Master'!B:B,0)),"0")) -> 9666495881
A13: 12 | B13: 44834 | C13: 7 | D13: 3948 | E13: 17500 | G13: =IF(TRIM(D13)="","",IFERROR(INDEX('Student Master'!AB:AB,MATCH(D13,'Student Master'!B:B,0)),"0")) -> 22000 | H13: =IF(TRIM(D13)="","",IFERROR(INDEX('Student Master'!AG:AG,MATCH(D13,'Student Master'!B:B,0)),"0")) -> 15000 | I13: =IF(TRIM(D13)="","",IFERROR(INDEX('Student Master'!AH:AH,MATCH(D13,'Student Master'!B:B,0)),"0")) -> 7000 | J13: =IF(TRIM(D13)="","",IFERROR(INDEX('Student Master'!AI:AI,MATCH(D13,'Student Master'!B:B,0)),"0")) -> 0 | K13: =IF(TRIM(D13)="","",E13/G13) -> 0.79545455 | M13: =IF(TRIM(D13)="","",IFERROR(INDEX('Student Master'!C:C,MATCH(D13,'Student Master'!B:B,0)),"0")) -> M. HITESH REDDY ® | N13: =IF(TRIM(D13)="","",IFERROR(INDEX('Student Master'!D:D,MATCH(D13,'Student Master'!B:B,0)),"0")) -> 6 - AM | O13: =IF(TRIM(D13)="","",IFERROR(INDEX('Student Master'!H:H,MATCH(D13,'Student Master'!B:B,0)),"0")) -> MADHAVA REDDY | P13: =IF(TRIM(D13)="","",IFERROR(INDEX('Student Master'!N:N,MATCH(D13,'Student Master'!B:B,0)),"0")) -> BHULAXMI CAMP | Q13: =IF(TRIM(D13)="","",IFERROR(INDEX('Student Master'!L:L,MATCH(D13,'Student Master'!B:B,0)),"0")) -> 9849137026
... A23: 22 | B23: 44779 | C23: 12 | D23: 4488 | E23: 15000 | G23: =IF(TRIM(D23)="","",IFERROR(INDEX('Student Master'!AB:AB,MATCH(D23,'Student Master'!B:B,0)),"0")) -> 16000 | H23: =IF(TRIM(D23)="","",IFERROR(INDEX('Student Master'!AG:AG,MATCH(D23,'Student Master'!B:B,0)),"0")) -> 10500 | I23: =IF(TRIM(D23)="","",IFERROR(INDEX('Student Master'!AH:AH,MATCH(D23,'Student Master'!B:B,0)),"0")) -> 5500 | J23: =IF(TRIM(D23)="","",IFERROR(INDEX('Student Master'!AI:AI,MATCH(D23,'Student Master'!B:B,0)),"0")) -> 0 | K23: =IF(TRIM(D23)="","",E23/G23) -> 0.9375 | M23: =IF(TRIM(D23)="","",IFERROR(INDEX('Student Master'!C:C,MATCH(D23,'Student Master'!B:B,0)),"0")) -> K. NAMRATHA | N23: =IF(TRIM(D23)="","",IFERROR(INDEX('Student Master'!D:D,MATCH(D23,'Student Master'!B:B,0)),"0")) -> 3 - BM | O23: =IF(TRIM(D23)="","",IFERROR(INDEX('Student Master'!H:H,MATCH(D23,'Student Master'!B:B,0)),"0")) -> K. BALAJI | P23: =IF(TRIM(D23)="","",IFERROR(INDEX('Student Master'!N:N,MATCH(D23,'Student Master'!B:B,0)),"0")) -> NAGANPALLY | Q23: =IF(TRIM(D23)="","",IFERROR(INDEX('Student Master'!L:L,MATCH(D23,'Student Master'!B:B,0)),"0")) -> 7893311870
A24: 23 | C24: 13 | D24: 4676 | E24: 20000 | G24: =IF(TRIM(D24)="","",IFERROR(INDEX('Student Master'!AB:AB,MATCH(D24,'Student Master'!B:B,0)),"0")) -> 26000 | H24: =IF(TRIM(D24)="","",IFERROR(INDEX('Student Master'!AG:AG,MATCH(D24,'Student Master'!B:B,0)),"0")) -> 10000 | I24: =IF(TRIM(D24)="","",IFERROR(INDEX('Student Master'!AH:AH,MATCH(D24,'Student Master'!B:B,0)),"0")) -> 0 | J24: =IF(TRIM(D24)="","",IFERROR(INDEX('Student Master'!AI:AI,MATCH(D24,'Student Master'!B:B,0)),"0")) -> 16000 | K24: =IF(TRIM(D24)="","",E24/G24) -> 0.76923077 | M24: =IF(TRIM(D24)="","",IFERROR(INDEX('Student Master'!C:C,MATCH(D24,'Student Master'!B:B,0)),"0")) -> B.RAKESH | N24: =IF(TRIM(D24)="","",IFERROR(INDEX('Student Master'!D:D,MATCH(D24,'Student Master'!B:B,0)),"0")) -> 2 - AS | O24: =IF(TRIM(D24)="","",IFERROR(INDEX('Student Master'!H:H,MATCH(D24,'Student Master'!B:B,0)),"0")) -> KARAN SINGH | P24: =IF(TRIM(D24)="","",IFERROR(INDEX('Student Master'!N:N,MATCH(D24,'Student Master'!B:B,0)),"0")) -> Neral Thanda | Q24: =IF(TRIM(D24)="","",IFERROR(INDEX('Student Master'!L:L,MATCH(D24,'Student Master'!B:B,0)),"0")) -> 9490534483
A25: 24 | C25: 13 | D25: 4677 | E25: 20000 | G25: =IF(TRIM(D25)="","",IFERROR(INDEX('Student Master'!AB:AB,MATCH(D25,'Student Master'!B:B,0)),"0")) -> 25000 | H25: =IF(TRIM(D25)="","",IFERROR(INDEX('Student Master'!AG:AG,MATCH(D25,'Student Master'!B:B,0)),"0")) -> 9500 | I25: =IF(TRIM(D25)="","",IFERROR(INDEX('Student Master'!AH:AH,MATCH(D25,'Student Master'!B:B,0)),"0")) -> 0 | J25: =IF(TRIM(D25)="","",IFERROR(INDEX('Student Master'!AI:AI,MATCH(D25,'Student Master'!B:B,0)),"0")) -> 15500 | K25: =IF(TRIM(D25)="","",E25/G25) -> 0.8 | M25: =IF(TRIM(D25)="","",IFERROR(INDEX('Student Master'!C:C,MATCH(D25,'Student Master'!B:B,0)),"0")) -> B. SOUNDHARYA | N25: =IF(TRIM(D25)="","",IFERROR(INDEX('Student Master'!D:D,MATCH(D25,'Student Master'!B:B,0)),"0")) -> 1 - AS | O25: =IF(TRIM(D25)="","",IFERROR(INDEX('Student Master'!H:H,MATCH(D25,'Student Master'!B:B,0)),"0")) -> B. KARAN SINGH | P25: =IF(TRIM(D25)="","",IFERROR(INDEX('Student Master'!N:N,MATCH(D25,'Student Master'!B:B,0)),"0")) -> Neral Thanda | Q25: =IF(TRIM(D25)="","",IFERROR(INDEX('Student Master'!L:L,MATCH(D25,'Student Master'!B:B,0)),"0")) -> 9490534483
A26: 25 | C26: 14 | D26: 4501 | E26: 12000 | G26: =IF(TRIM(D26)="","",IFERROR(INDEX('Student Master'!AB:AB,MATCH(D26,'Student Master'!B:B,0)),"0")) -> 16000 | H26: =IF(TRIM(D26)="","",IFERROR(INDEX('Student Master'!AG:AG,MATCH(D26,'Student Master'!B:B,0)),"0")) -> 9000 | I26: =IF(TRIM(D26)="","",IFERROR(INDEX('Student Master'!AH:AH,MATCH(D26,'Student Master'!B:B,0)),"0")) -> 7000 | J26: =IF(TRIM(D26)="","",IFERROR(INDEX('Student Master'!AI:AI,MATCH(D26,'Student Master'!B:B,0)),"0")) -> 0 | K26: =IF(TRIM(D26)="","",E26/G26) -> 0.75 | M26: =IF(TRIM(D26)="","",IFERROR(INDEX('Student Master'!C:C,MATCH(D26,'Student Master'!B:B,0)),"0")) -> CH. AARTHI NAGA SAI | N26: =IF(TRIM(D26)="","",IFERROR(INDEX('Student Master'!D:D,MATCH(D26,'Student Master'!B:B,0)),"0")) -> U - BM | O26: =IF(TRIM(D26)="","",IFERROR(INDEX('Student Master'!H:H,MATCH(D26,'Student Master'!B:B,0)),"0")) -> ANAND | P26: =IF(TRIM(D26)="","",IFERROR(INDEX('Student Master'!N:N,MATCH(D26,'Student Master'!B:B,0)),"0")) -> PANTAKHURD OLD | Q26: =IF(TRIM(D26)="","",IFERROR(INDEX('Student Master'!L:L,MATCH(D26,'Student Master'!B:B,0)),"0")) -> 9866673755
A27: 26 | C27: 14 | D27: 4195 | E27: 13000 | G27: =IF(TRIM(D27)="","",IFERROR(INDEX('Student Master'!AB:AB,MATCH(D27,'Student Master'!B:B,0)),"0")) -> 17000 | H27: =IF(TRIM(D27)="","",IFERROR(INDEX('Student Master'!AG:AG,MATCH(D27,'Student Master'!B:B,0)),"0")) -> 10000 | I27: =IF(TRIM(D27)="","",IFERROR(INDEX('Student Master'!AH:AH,MATCH(D27,'Student Master'!B:B,0)),"0")) -> 7000 | J27: =IF(TRIM(D27)="","",IFERROR(INDEX('Student Master'!AI:AI,MATCH(D27,'Student Master'!B:B,0)),"0")) -> 0 | K27: =IF(TRIM(D27)="","",E27/G27) -> 0.76470588 | M27: =IF(TRIM(D27)="","",IFERROR(INDEX('Student Master'!C:C,MATCH(D27,'Student Master'!B:B,0)),"0")) -> CH. TEJASVI | N27: =IF(TRIM(D27)="","",IFERROR(INDEX('Student Master'!D:D,MATCH(D27,'Student Master'!B:B,0)),"0")) -> 2 - BM | O27: =IF(TRIM(D27)="","",IFERROR(INDEX('Student Master'!H:H,MATCH(D27,'Student Master'!B:B,0)),"0")) -> CH. ANAND | P27: =IF(TRIM(D27)="","",IFERROR(INDEX('Student Master'!N:N,MATCH(D27,'Student Master'!B:B,0)),"0")) -> PANTA CAMP | Q27: =IF(TRIM(D27)="","",IFERROR(INDEX('Student Master'!L:L,MATCH(D27,'Student Master'!B:B,0)),"0")) -> 9866673755
A28: 27 | C28: 15 | D28: 3632 | E28: 40000 | G28: =IF(TRIM(D28)="","",IFERROR(INDEX('Student Master'!AB:AB,MATCH(D28,'Student Master'!B:B,0)),"0")) -> 47000 | H28: =IF(TRIM(D28)="","",IFERROR(INDEX('Student Master'!AG:AG,MATCH(D28,'Student Master'!B:B,0)),"0")) -> 25000 | I28: =IF(TRIM(D28)="","",IFERROR(INDEX('Student Master'!AH:AH,MATCH(D28,'Student Master'!B:B,0)),"0")) -> 0 | J28: =IF(TRIM(D28)="","",IFERROR(INDEX('Student Master'!AI:AI,MATCH(D28,'Student Master'!B:B,0)),"0")) -> 22000 | K28: =IF(TRIM(D28)="","",E28/G28) -> 0.85106383 | M28: =IF(TRIM(D28)="","",IFERROR(INDEX('Student Master'!C:C,MATCH(D28,'Student Master'!B:B,0)),"0")) -> M. SAI KUMAR | N28: =IF(TRIM(D28)="","",IFERROR(INDEX('Student Master'!D:D,MATCH(D28,'Student Master'!B:B,0)),"0")) -> 10 - AS | O28: =IF(TRIM(D28)="","",IFERROR(INDEX('Student Master'!H:H,MATCH(D28,'Student Master'!B:B,0)),"0")) -> NARSIMHA | P28: =IF(TRIM(D28)="","",IFERROR(INDEX('Student Master'!N:N,MATCH(D28,'Student Master'!B:B,0)),"0")) -> L.B.S. NAGAR | Q28: =IF(TRIM(D28)="","",IFERROR(INDEX('Student Master'!L:L,MATCH(D28,'Student Master'!B:B,0)),"0")) -> 7729825412
A29: 28 | C29: 16 | D29: 3082 | E29: 41500 | G29: =IF(TRIM(D29)="","",IFERROR(INDEX('Student Master'!AB:AB,MATCH(D29,'Student Master'!B:B,0)),"0")) -> 47000 | H29: =IF(TRIM(D29)="","",IFERROR(INDEX('Student Master'!AG:AG,MATCH(D29,'Student Master'!B:B,0)),"0")) -> 25000 | I29: =IF(TRIM(D29)="","",IFERROR(INDEX('Student Master'!AH:AH,MATCH(D29,'Student Master'!B:B,0)),"0")) -> 0 | J29: =IF(TRIM(D29)="","",IFERROR(INDEX('Student Master'!AI:AI,MATCH(D29,'Student Master'!B:B,0)),"0")) -> 22000 | K29: =IF(TRIM(D29)="","",E29/G29) -> 0.88297872 | M29: =IF(TRIM(D29)="","",IFERROR(INDEX('Student Master'!C:C,MATCH(D29,'Student Master'!B:B,0)),"0")) -> S. ARUN | N29: =IF(TRIM(D29)="","",IFERROR(INDEX('Student Master'!D:D,MATCH(D29,'Student Master'!B:B,0)),"0")) -> 10 - AS | O29: =IF(TRIM(D29)="","",IFERROR(INDEX('Student Master'!H:H,MATCH(D29,'Student Master'!B:B,0)),"0")) -> GANGARAM | P29: =IF(TRIM(D29)="","",IFERROR(INDEX('Student Master'!N:N,MATCH(D29,'Student Master'!B:B,0)),"0")) -> BARDIPUR | Q29: =IF(TRIM(D29)="","",IFERROR(INDEX('Student Master'!L:L,MATCH(D29,'Student Master'!B:B,0)),"0")) -> 9133894901
A30: 29 | C30: 17 | D30: 3788 | E30: 13000 | G30: =IF(TRIM(D30)="","",IFERROR(INDEX('Student Master'!AB:AB,MATCH(D30,'Student Master'!B:B,0)),"0")) -> 18500 | H30: =IF(TRIM(D30)="","",IFERROR(INDEX('Student Master'!AG:AG,MATCH(D30,'Student Master'!B:B,0)),"0")) -> 11500 | I30: =IF(TRIM(D30)="","",IFERROR(INDEX('Student Master'!AH:AH,MATCH(D30,'Student Master'!B:B,0)),"0")) -> 7000 | J30: =IF(TRIM(D30)="","",IFERROR(INDEX('Student Master'!AI:AI,MATCH(D30,'Student Master'!B:B,0)),"0")) -> 0 | K30: =IF(TRIM(D30)="","",E30/G30) -> 0.7027027 | M30: =IF(TRIM(D30)="","",IFERROR(INDEX('Student Master'!C:C,MATCH(D30,'Student Master'!B:B,0)),"0")) -> D. PRIYANS | N30: =IF(TRIM(D30)="","",IFERROR(INDEX('Student Master'!D:D,MATCH(D30,'Student Master'!B:B,0)),"0")) -> 4 - BM | O30: =IF(TRIM(D30)="","",IFERROR(INDEX('Student Master'!H:H,MATCH(D30,'Student Master'!B:B,0)),"0")) -> D. SRINIVAS | P30: =IF(TRIM(D30)="","",IFERROR(INDEX('Student Master'!N:N,MATCH(D30,'Student Master'!B:B,0)),"0")) -> YEDAPALLY | Q30: =IF(TRIM(D30)="","",IFERROR(INDEX('Student Master'!L:L,MATCH(D30,'Student Master'!B:B,0)),"0")) -> 9951339582
A31: 30 | C31: 18 | D31: 4739 | E31: 13000 | G31: =IF(TRIM(D31)="","",IFERROR(INDEX('Student Master'!AB:AB,MATCH(D31,'Student Master'!B:B,0)),"0")) -> 17000 | H31: =IF(TRIM(D31)="","",IFERROR(INDEX('Student Master'!AG:AG,MATCH(D31,'Student Master'!B:B,0)),"0")) -> 10000 | I31: =IF(TRIM(D31)="","",IFERROR(INDEX('Student Master'!AH:AH,MATCH(D31,'Student Master'!B:B,0)),"0")) -> 7000 | J31: =IF(TRIM(D31)="","",IFERROR(INDEX('Student Master'!AI:AI,MATCH(D31,'Student Master'!B:B,0)),"0")) -> 0 | K31: =IF(TRIM(D31)="","",E31/G31) -> 0.76470588 | M31: =IF(TRIM(D31)="","",IFERROR(INDEX('Student Master'!C:C,MATCH(D31,'Student Master'!B:B,0)),"0")) -> A.NAMRATA | N31: =IF(TRIM(D31)="","",IFERROR(INDEX('Student Master'!D:D,MATCH(D31,'Student Master'!B:B,0)),"0")) -> 2 - AM | O31: =IF(TRIM(D31)="","",IFERROR(INDEX('Student Master'!H:H,MATCH(D31,'Student Master'!B:B,0)),"0")) -> VENKATESH | P31: =IF(TRIM(D31)="","",IFERROR(INDEX('Student Master'!N:N,MATCH(D31,'Student Master'!B:B,0)),"0")) -> PANTAKHURD OLD | Q31: =IF(TRIM(D31)="","",IFERROR(INDEX('Student Master'!L:L,MATCH(D31,'Student Master'!B:B,0)),"0")) -> 9640896717
A32: 31 | C32: 18 | D32: 4674 | E32: 15000 | G32: =IF(TRIM(D32)="","",IFERROR(INDEX('Student Master'!AB:AB,MATCH(D32,'Student Master'!B:B,0)),"0")) -> 19500 | H32: =IF(TRIM(D32)="","",IFERROR(INDEX('Student Master'!AG:AG,MATCH(D32,'Student Master'!B:B,0)),"0")) -> 12500 | I32: =IF(TRIM(D32)="","",IFERROR(INDEX('Student Master'!AH:AH,MATCH(D32,'Student Master'!B:B,0)),"0")) -> 7000 | J32: =IF(TRIM(D32)="","",IFERROR(INDEX('Student Master'!AI:AI,MATCH(D32,'Student Master'!B:B,0)),"0")) -> 0 | K32: =IF(TRIM(D32)="","",E32/G32) -> 0.76923077 | M32: =IF(TRIM(D32)="","",IFERROR(INDEX('Student Master'!C:C,MATCH(D32,'Student Master'!B:B,0)),"0")) -> A.NAGA CHAITANYA | N32: =IF(TRIM(D32)="","",IFERROR(INDEX('Student Master'!D:D,MATCH(D32,'Student Master'!B:B,0)),"0")) -> 5 - BM | O32: =IF(TRIM(D32)="","",IFERROR(INDEX('Student Master'!H:H,MATCH(D32,'Student Master'!B:B,0)),"0")) -> VENKATESH | P32: =IF(TRIM(D32)="","",IFERROR(INDEX('Student Master'!N:N,MATCH(D32,'Student Master'!B:B,0)),"0")) -> PANTAKHURD OLD | Q32: =IF(TRIM(D32)="","",IFERROR(INDEX('Student Master'!L:L,MATCH(D32,'Student Master'!B:B,0)),"0")) -> 9640896717
A33: 32 | C33: 19 | D33: 4148 | E33: 8000 | G33: =IF(TRIM(D33)="","",IFERROR(INDEX('Student Master'!AB:AB,MATCH(D33,'Student Master'!B:B,0)),"0")) -> 9500 | H33: =IF(TRIM(D33)="","",IFERROR(INDEX('Student Master'!AG:AG,MATCH(D33,'Student Master'!B:B,0)),"0")) -> 9500 | I33: =IF(TRIM(D33)="","",IFERROR(INDEX('Student Master'!AH:AH,MATCH(D33,'Student Master'!B:B,0)),"0")) -> 0 | J33: =IF(TRIM(D33)="","",IFERROR(INDEX('Student Master'!AI:AI,MATCH(D33,'Student Master'!B:B,0)),"0")) -> 0 | K33: =IF(TRIM(D33)="","",E33/G33) -> 0.84210526 | M33: =IF(TRIM(D33)="","",IFERROR(INDEX('Student Master'!C:C,MATCH(D33,'Student Master'!B:B,0)),"0")) -> MEER NOMAN ALI | N33: =IF(TRIM(D33)="","",IFERROR(INDEX('Student Master'!D:D,MATCH(D33,'Student Master'!B:B,0)),"0")) -> 1 - AM | O33: =IF(TRIM(D33)="","",IFERROR(INDEX('Student Master'!H:H,MATCH(D33,'Student Master'!B:B,0)),"0")) -> MEER KHADAR ALI | P33: =IF(TRIM(D33)="","",IFERROR(INDEX('Student Master'!N:N,MATCH(D33,'Student Master'!B:B,0)),"0")) -> SHARBATHI CANAL | Q33: =IF(TRIM(D33)="","",IFERROR(INDEX('Student Master'!L:L,MATCH(D33,'Student Master'!B:B,0)),"0")) -> 9010209080 | R33: repeated
A34: 33 | C34: 20 | D34: 2875 | E34: 19000 | G34: =IF(TRIM(D34)="","",IFERROR(INDEX('Student Master'!AB:AB,MATCH(D34,'Student Master'!B:B,0)),"0")) -> 23500 | H34: =IF(TRIM(D34)="","",IFERROR(INDEX('Student Master'!AG:AG,MATCH(D34,'Student Master'!B:B,0)),"0")) -> 18000 | I34: =IF(TRIM(D34)="","",IFERROR(INDEX('Student Master'!AH:AH,MATCH(D34,'Student Master'!B:B,0)),"0")) -> 5500 | J34: =IF(TRIM(D34)="","",IFERROR(INDEX('Student Master'!AI:AI,MATCH(D34,'Student Master'!B:B,0)),"0")) -> 0 | K34: =IF(TRIM(D34)="","",E34/G34) -> 0.80851064 | M34: =IF(TRIM(D34)="","",IFERROR(INDEX('Student Master'!C:C,MATCH(D34,'Student Master'!B:B,0)),"0")) -> D. KEERTHANA | N34: =IF(TRIM(D34)="","",IFERROR(INDEX('Student Master'!D:D,MATCH(D34,'Student Master'!B:B,0)),"0")) -> 8 - AM | O34: =IF(TRIM(D34)="","",IFERROR(INDEX('Student Master'!H:H,MATCH(D34,'Student Master'!B:B,0)),"0")) -> D. BHEEM SHANKAR | P34: =IF(TRIM(D34)="","",IFERROR(INDEX('Student Master'!N:N,MATCH(D34,'Student Master'!B:B,0)),"0")) -> NAGANPALLY | Q34: =IF(TRIM(D34)="","",IFERROR(INDEX('Student Master'!L:L,MATCH(D34,'Student Master'!B:B,0)),"0")) -> 7702752667
A35: 34 | C35: 20 | D35: 4069 | E35: 13000 | G35: =IF(TRIM(D35)="","",IFERROR(INDEX('Student Master'!AB:AB,MATCH(D35,'Student Master'!B:B,0)),"0")) -> 16000 | H35: =IF(TRIM(D35)="","",IFERROR(INDEX('Student Master'!AG:AG,MATCH(D35,'Student Master'!B:B,0)),"0")) -> 10500 | I35: =IF(TRIM(D35)="","",IFERROR(INDEX('Student Master'!AH:AH,MATCH(D35,'Student Master'!B:B,0)),"0")) -> 5500 | J35: =IF(TRIM(D35)="","",IFERROR(INDEX('Student Master'!AI:AI,MATCH(D35,'Student Master'!B:B,0)),"0")) -> 0 | K35: =IF(TRIM(D35)="","",E35/G35) -> 0.8125 | M35: =IF(TRIM(D35)="","",IFERROR(INDEX('Student Master'!C:C,MATCH(D35,'Student Master'!B:B,0)),"0")) -> D. NIKITHA | N35: =IF(TRIM(D35)="","",IFERROR(INDEX('Student Master'!D:D,MATCH(D35,'Student Master'!B:B,0)),"0")) -> 3 - AM | O35: =IF(TRIM(D35)="","",IFERROR(INDEX('Student Master'!H:H,MATCH(D35,'Student Master'!B:B,0)),"0")) -> D. BHEEM SHANKAR | P35: =IF(TRIM(D35)="","",IFERROR(INDEX('Student Master'!N:N,MATCH(D35,'Student Master'!B:B,0)),"0")) -> NAGANPALLY | Q35: =IF(TRIM(D35)="","",IFERROR(INDEX('Student Master'!L:L,MATCH(D35,'Student Master'!B:B,0)),"0")) -> 7702752667
A36: 35 | C36: 21 | D36: 4442 | E36: 13500 | G36: =IF(TRIM(D36)="","",IFERROR(INDEX('Student Master'!AB:AB,MATCH(D36,'Student Master'!B:B,0)),"0")) -> 17500 | H36: =IF(TRIM(D36)="","",IFERROR(INDEX('Student Master'!AG:AG,MATCH(D36,'Student Master'!B:B,0)),"0")) -> 9500 | I36: =IF(TRIM(D36)="","",IFERROR(INDEX('Student Master'!AH:AH,MATCH(D36,'Student Master'!B:B,0)),"0")) -> 8000 | J36: =IF(TRIM(D36)="","",IFERROR(INDEX('Student Master'!AI:AI,MATCH(D36,'Student Master'!B:B,0)),"0")) -> 0 | K36: =IF(TRIM(D36)="","",E36/G36) -> 0.77142857 | M36: =IF(TRIM(D36)="","",IFERROR(INDEX('Student Master'!C:C,MATCH(D36,'Student Master'!B:B,0)),"0")) -> MD. MIRZA ABBU BAQAR | N36: =IF(TRIM(D36)="","",IFERROR(INDEX('Student Master'!D:D,MATCH(D36,'Student Master'!B:B,0)),"0")) -> 1 - BM | O36: =IF(TRIM(D36)="","",IFERROR(INDEX('Student Master'!H:H,MATCH(D36,'Student Master'!B:B,0)),"0")) -> MIRZA AZMATH BAIG | P36: =IF(TRIM(D36)="","",IFERROR(INDEX('Student Master'!N:N,MATCH(D36,'Student Master'!B:B,0)),"0")) -> KOPPARGA | Q36: =IF(TRIM(D36)="","",IFERROR(INDEX('Student Master'!L:L,MATCH(D36,'Student Master'!B:B,0)),"0")) -> 7569194416
